Workbook

Sheet Tabla
A1: CONCEPTO | B1: TIPO | C1: % | D1: IMPORTE
A2: IMPUESTO | B2: IIBB | C2: 0.04 | D2: 0
A3: IMPUESTO | B3: IVA | C3: 0.21 | D3: 0
A4: IMPUESTO | B4: DEBITO Y CREDITO | C4: 0.012 | D4: 0
A5: TRANSACCIONES | B5: MP (10 días) | C5: 0.06 | D5: 0
A6: TRANSACCIONES | B6: Comisión por Cheque | C6: 0.025 | D6: 0
A7: PRECIO | B7: Producto 1 | C7: 0 | D7: 1200
A8: PRECIO | B8: Producto 2 | C8: 0 | D8: 500

Sheet PUNTO DE EQUILIBRIO
A1: PRECIO USD | B1: 1200
A3: PUNTO DE EQULIBRO (Q)
B4: USD
A5: AÑO 1
A6: PREVIO VTA. UNITARIO | B6: 50
A7: COST. VARIABLE UNITARIO | B7: 5
A8: SUSCRIPCIONES POR AÑO DE EQUILIBRIO | B8: =((B5/(B6-B7))) -> 0

Sheet Tabla Empleados
A1: PUESTO | B1: DETALLE | C1: MES 1 | D1: MES 2 | E1: MES 3 | F1: MES 4 | G1: MES 5 | H1: X | I1: AÑO 1 | J1: MES 1 3 | K1: MES 14
A2: Administrativo | B2: Cantidad | C2: 1 | D2: 2 | I2: =+G2+F29+E2+D2+C2 -> 3
B3: Remunerción neta | C3: 1000000 | D3: 1000000 | I3: =+G3+F30+E3+D3+C3 -> 2000000
B4: Remuneración Bruta | C4: =+C3*1.45 -> 1450000 | D4: =+D3*1.45 -> 1450000 | I4: =+G4+F31+E4+D4+C4 -> 2900000
B5: Total a Pagar | C5: =+C4*C2 -> 1450000 | D5: =+D4*D2 -> 2900000 | I5: =+G5+F32+E5+D5+C5 -> 4350000
A6: Gerente X | B6: Cantidad | C6: 1 | D6: 3 | I6: =+G6+F33+E6+D6+C6 -> 4
B7: Remunerción neta | C7: 1000000 | D7: 1000000 | I7: =+G7+F34+E7+D7+C7 -> 2000000
B8: Remuneración Bruta | C8: =+C7*1.45 -> 1450000 | D8: =+D7*1.45 -> 1450000 | I8: =+G8+F35+E8+D8+C8 -> 2900000
B9: Total a Pagar | C9: =+C8*C6 -> 1450000 | D9: =+D8*D6 -> 4350000 | I9: =+G9+F36+E9+D9+C9 -> 5800000
A10: Seguridad X | B10: Cantidad | C10: 1 | D10: 1 | I10: =+G10+F37+E10+D10+C10 -> 2
B11: Remunerción neta | C11: 1000000 | D11: 1000000 | I11: =+G11+F38+E11+D11+C11 -> 2000000
B12: Remuneración Bruta | C12: =+C11*1.45 -> 1450000 | D12: =+D11*1.45 -> 1450000 | I12: =+G12+F39+E12+D12+C12 -> 2900000
B13: Total a Pagar | C13: =+C12*C10 -> 1450000 | D13: =+D12*D10 -> 1450000 | I13: =+G13+F40+E13+D13+C13 -> 2900000
A14: Cientifico Labo. | B14: Cantidad | C14: 1 | D14: 2 | I14: =+G14+F41+E14+D14+C14 -> 3
B15: Remunerción neta | C15: 1000000 | D15: 1000000 | I15: =+G15+F42+E15+D15+C15 -> 2000000
B16: Remuneración Bruta | C16: =+C15*1.45 -> 1450000 | D16: =+D15*1.45 -> 1450000 | I16: =+G16+F43+E16+D16+C16 -> 2900000
B17: Total a Pagar | C17: =+C16*C14 -> 1450000 | D17: =+D16*D14 -> 2900000 | I17: =+G17+F44+E17+D17+C17 -> 4350000
I18: =+G18+F45+E18+D18+C18 -> 0
A19: Total Sueldos en ARS | C19: =+C17+C13+C9+C5 -> 5800000 | D19: =+D17+D13+D9+D5 -> 11600000 | I19: =+G19+F46+E19+D19+C19 -> 17400000
A20: Total Sueldos en USD | C20: =+C19/1430 -> 4055.9441 | D20: =+D19/1430 -> 8111.8881 | I20: =+G20+F47+E20+D20+C20 -> 12167.832
A23: Total Empleados | C23: =+C14+C10+C6+C2 -> 4 | D23: =+D14+D10+D6+D2 -> 8 | E23: =+E14+E10+E6+E2 -> 0 | F23: =+F14+F10+F6+F2 -> 0 | G23: =+G14+G10+G6+G2 -> 0 | H23: =+H14+H10+H6+H2 -> 0 | I23: =+I14+I10+I6+I2 -> 12

Sheet FF Ejemplo
A1: VENTAS | B1: MES 1 | C1: MES 2
A2: Sus. Basic | B2: 200 | C2: 2000
A3: Sus. Platinum | B3: 100 | C3: 650
A4: Enterprice | B4: 5 | C4: =+B4*1.07 -> 5.35
A5: Sus. USD35 | B5: =+B2*35 -> 7000 | C5: =+C2*35 -> 70000
A6: Sus. USD60 | B6: =+B3*60 -> 6000 | C6: =+C3*60 -> 39000
A7: Enterprice (2500) | B7: =+B4*2500 -> 12500 | C7: =+C4*2500 -> 13375
A8: Total de Ingresos Por Venta | B8: =+B5+B6+B7 -> 25500 | C8: =+C5+C6+C7 -> 122375
A9: COSTOS VARIABLES | B9: MES 1 | C9: MES 2
A10: IIBB | B10: =+B8*Tabla!$C$2 -> 1020 | C10: =+B10*1.07 -> 1091.4
A11: Servicio Transaccional | B11: =+B8*Tabla!$C$5 -> 1530 | C11: =+B11*1.07 -> 1637.1
A12: e-mail Transaccional | B12: 200 | C12: =+B12*1.07 -> 214
A13: Comisiones Vendedor | B13: =+B7*(0.1) -> 1250 | C13: =+B13*1.07 -> 1337.5
A14: Varios | B14: 3000 | C14: =+B14*1.07 -> 3210
A15: Total de Ingresos Por Venta | B15: =+SUM(B10:B14) -> 7000 | C15: =+SUM(C10:C14) -> 7490
A16: MARGEN BRUTO | B16: =+B8-B15 -> 18500 | C16: =+C8-C15 -> 114885
A17: COSTO VARIABLES | B17: MES 1 | C17: MES 2
A18: Gast. Administrativos
A19: Oficina (Cowork) | B19: =350*'Tabla Empleados'!$C$23 -> 1400 | C19: =+B19 -> 1400
A20: Abogado | B20: 150 | C20: =+B20 -> 150
A21: Contador | B21: 150 | C21: =+B21 -> 150
A22: Banco | B22: 50 | C22: =+B22 -> 50
A23: Seguros | B23: 100 | C23: =+B23 -> 100
A24: Gastos beneficios RRHH | B24: =((30000*11)+(4000*11*22)+(32000*11)+(400000*11)+(12*30))/'PUNTO DE EQUILIBRIO'!$B$1 -> 5041.9667 | C24: =+B24 -> 5041.9667
A25: Insmos de Oficina | B25: =100000/'PUNTO DE EQUILIBRIO'!B1 -> 83.333333 | C25: =+B25 -> 83.333333
A26: Alta de sociedad | B26: =1000000/'PUNTO DE EQUILIBRIO'!B1 -> 833.33333 | C26: 0
A27: Sueldos | B27: =((2*4000)+(1*1500))*1.65 -> 15675 | C27: =+B27 -> 15675
A28: Viaticos Ejecutivos | B28: 800 | C28: =+B28 -> 800
A29: Software de Adm (ERP, Contable) | B29: =7*50 -> 350 | C29: =+B29 -> 350
A30: Servicio de ofimática | B30: =11*20 -> 220 | C30: =+B30 -> 220
A31: TOTAL GASTOS ADMINISTRATIVOS: | B31: =SUM(B19:B29) -> 24633.633 | C31: =SUM(C19:C29) -> 23800.3
A32: Gast. Operativos
A33: Bienes de Uso Tech | B33: =('Tabla Empleados'!$C$23*2500)+(100*11)+(900*5)+(400*7) -> 18400 | C33: 0
A34: Bienes de uso General | B34: 300 | C34: =+B34 -> 300
A35: Infraestructura de Hosting y Plataformas | B35: =(50+(5*30)) -> 200 | C35: =+B35 -> 200
A36: Sueldos | B36: =((1*4000)+(7*2500))*1.65 -> 35475 | C36: =+B36 -> 35475
A37: Herramientas de Dev y Control | B37: =(30*11)+(25*7) -> 505 | C37: =+B37 -> 505
A38: VPN | B38: =10*13 -> 130 | C38: =+B38 -> 130
A39: Open AI | B39: 200 | C39: =+B39 -> 200
A40: TOTAL GASTOS OPRATIVOS: | B40: =SUM(B33:B38) -> 55010 | C40: =SUM(C33:C38) -> 36610
...
